Workbook

Sheet FK Map
A1: S.No. | B1: Table | C1: Column | D1: Reference Table | E1: Reference Column | F1: Cardinality
A2: 1 | B2: Sales_SKU | C2: SKU Code | D2: Material Master | E2: SKU Code | F2: One to one
A3: 2 | B3: Sales_SKU | C3: plant | D3: Plants | E3: plant_code | F3: Many to one
A4: 3 | B4: Sales_SKU | C4: market_eligibility | D4: Regions | E4: region_id | F4: Many to one
A5: 4 | B5: Purchase_SKU | C5: SKU code | D5: Material Master | E5: SKU Code | F5: One to one
A6: 5 | B6: BOM_Line Item | C6: FG SKU Code | D6: Sales_SKU | E6: SKU Code | F6: Many to one
A7: 6 | B7: BOM_Line Item | C7: RM ID | D7: Purchase_SKU | E7: rm_id | F7: Many to one
A8: 7 | B8: BOM_Line Item | C8: RM SKU Code | D8: Material Master | E8: SKU Code | F8: Many to one
A9: 8 | B9: Countries | C9: region_id | D9: Regions | E9: region_id | F9: Many to one
A10: 9 | B10: Customers | C10: country_iso | D10: Countries | E10: iso_code | F10: Many to one
A11: 10 | B11: Customers | C11: customer_region_id | D11: Regions | E11: region_id | F11: Many to one
A12: 11 | B12: SLA Profiles | C12: scope_region_id | D12: Regions | E12: region_id | F12: Many to one
A13: 12 | B13: Orders | C13: Customer ID | D13: Customers | E13: customer_id | F13: Many to one
... A69: 68 | B69: Lessons | C69: Review ID | D69: Review Events | E69: Review Event ID | F69: Many to one

Sheet Material Master
A1: SKU Code (Primary Key) | B1: cas_number | C1: hazard_class | D1: shelf_life_months
A2: ESS-ACETYL-ETHACE-LM-98.5-NEAT-BULK-DST | B2: 141-78-6 | C2: Flam. Liq. 2 | D2: 24
A3: ESS-ACETYL-ETHACE-LM-98.5-NEAT-BULK-DST | B3: 141-78-6 | C3: Flam. Liq. 2 | D3: 24
A4: ESS-ACETYL-ETHACE-LM-98.5-NEAT-BULK-DST | B4: 141-78-6 | C4: Flam. Liq. 2 | D4: 24
A5: SPI-ACETYL-ACEANH-PH-98.6-NEAT-DR200_UN-MHD | B5: 108-24-7 | C5: Skin Corr. 1B | D5: 24
A6: SPI-ACETYL-ACEANH-PH-98.6-NEAT-DR200_UN-MHD | B6: 108-24-7 | C6: Skin Corr. 1B | D6: 24
A7: SPI-ACETYL-ACEANH-PH-98.6-NEAT-DR200_UN-MHD | B7: 108-24-7 | C7: Skin Corr. 1B | D7: 24
A8: SPI-ACETYL-ACE-IND-98.4-NEAT-ISO20-LTE | B8: 75-07-0 | C8: Flam. Liq. 2; Acute Tox. 3 | D8: 12
A9: SPI-ACETYL-ACE-IND-98.4-NEAT-ISO20-LTE | B9: 75-07-0 | C9: Flam. Liq. 2; Acute Tox. 3 | D9: 12
A10: SPI-ACETYL-ACE-IND-98.4-NEAT-ISO20-LTE | B10: 75-07-0 | C10: Flam. Liq. 2; Acute Tox. 3 | D10: 12
A11: ESS-ACETYL-BUTACE-TECH-98.3-NEAT-DR200-DHJ | B11: 123-86-4 | C11: Flam. Liq. 3 | D11: 24
A12: ESS-ACETYL-BUTACE-TECH-98.3-NEAT-DR200-DHJ | B12: 123-86-4 | C12: Flam. Liq. 3 | D12: 24
A13: ESS-ACETYL-BUTACE-TECH-98.3-NEAT-DR200-DHJ | B13: 123-86-4 | C13: Flam. Liq. 3 | D13: 24
... A130: RM-DIK-ET-88412 | B130: 674-82-8 | C130: Flam. Liq. 2 | D130: 12
A131: INT-KET-INS-145120 | B131: 463-51-4 | C131: Flam. Gas 1; Acute Tox. 2
A132: INT-DKD-INT-342781 | C132: Flam. Liq. 3 | D132: 12
A133: INT-ARY-INT-558903 | C133: Skin Irrit. 2 | D133: 12
A134: INT-FLR-BLK-903117 | C134: DG (Fluoro) | D134: 12
A135: RM-SUL-AC-10477 | B135: 7664-93-9 | C135: Skin Corr. 1A | D135: 36
A136: RM-HCL-32-65019 | B136: 7647-01-0 | C136: Skin Corr. 1B | D136: 24
A137: RM-NAO-CP-77811 | B137: 1310-73-2 | C137: Skin Corr. 1A | D137: 36
A138: RM-ACN-SV-33120 | B138: 75-05-8 | C138: Flam. Liq. 2 | D138: 36
A139: RM-TOL-SV-90412 | B139: 108-88-3 | C139: Flam. Liq. 2 | D139: 36
A140: RM-MEO-SV-11024 | B140: 67-56-1 | C140: Flam. Liq. 2; Acute Tox. 3 | D140: 36
A141: RM-PDH-CB-61302 | B141: 7440-05-3 | D141: 36
A142: RM-PTC-CAT-27190 | B142: 1643-19-2 | C142: Acute Tox. 4 | D142: 36
A143: PACK-DRM-HD-20001
A144: PACK-IBC-IB-10002
A145: PACK-BAG-PP-25003
A146: PACK-LIN-FX-12004
A147: PACK-SEA-DR-33005
A148: INT-ACE-ANH-772001 | B148: 108-24-7 | C148: Skin Corr. 1B | D148: 12
A149: INT-AAA-EMM-990812 | D149: 12
A150: RM-ETH-AL-64197 | B150: 64-19-7 | C150: Flam. Liq. 2 | D150: 24
A151: RM-ETH-AL-64219 | B151: 64-21-9 | C151: Flam. Liq. 2 | D151: 24
A152: RM-ETH-AL-64241 | B152: 64-24-1 | C152: Flam. Liq. 2 | D152: 24
A153: INT-KET-674828 | B153: 674-82-8 | C153: Flam. Liq. 1; Acute Tox. 2 | D153: 6
A154: INT-KET-463514 | B154: 463-51-4 | C154: Flam. Gas 1; Acute Tox. 2 | D154: 6
A155: PKG-DR200 | B155: N/A | C155: Non-Hazardous | D155: 60
A156: PKG-DR200_UN | B156: N/A | C156: Non-Hazardous (UN Certified) | D156: 60
...

Sheet Sales_SKU
A1: FG_Primary Key | B1: SKU Code (FK) | C1: business_unit | D1: Product family | E1: Product Sub-group (molecule_name) | F1: Variant (grade) | G1: Spec 1 (key_specs_assay_pct) | H1: Spec 2 (key_specs_moisture_ppm) | I1: Spec 3 (key_specs_color_apha) | J1: form | K1: packaging | L1: UOM | M1: plant (plant FK) | N1: market_eligibility (regions FK) | O1: regulatory_set_id
A2: FG01 | B2: ESS-ACETYL-ETHACE-LM-98.5-NEAT-BULK-DST | C2: Essentials | D2: ACETYL | E2: Ethyl Acetate | F2: LM | G2: 98.3 | H2: 233 | I2: 17 | J2: =IF(ISNUMBER(SEARCH("-NEAT-",Sales_SKU!$B2)),"Neat",IF(ISNUMBER(SEARCH("-PWD-",Sales_SKU!$B2)),"powder","")) -> Neat | K2: BULK | L2: =IF(J2="Neat","KL",IF(J2="PWD","MT","MT")) -> KL | M2: DST | N2: DOM | O2: REG-IN-ACETYL-LM
A3: FG02 | B3: ESS-ACETYL-ETHACE-LM-98.5-NEAT-BULK-DST | C3: Essentials | D3: ACETYL | E3: Ethyl Acetate | F3: LM | G3: 98.3 | H3: 246 | I3: 19 | J3: =IF(ISNUMBER(SEARCH("-NEAT-",Sales_SKU!$B3)),"Neat",IF(ISNUMBER(SEARCH("-PWD-",Sales_SKU!$B3)),"powder","")) -> Neat | K3: BULK | L3: =IF(J3="Neat","KL",IF(J3="PWD","MT","MT")) -> KL | M3: DST | N3: EU | O3: REG-EU-ACETYL-LM
A4: FG03 | B4: ESS-ACETYL-ETHACE-LM-98.5-NEAT-BULK-DST | C4: Essentials | D4: ACETYL | E4: Ethyl Acetate | F4: LM | G4: 98.3 | H4: 259 | I4: 23 | J4: =IF(ISNUMBER(SEARCH("-NEAT-",Sales_SKU!$B4)),"Neat",IF(ISNUMBER(SEARCH("-PWD-",Sales_SKU!$B4)),"powder","")) -> Neat | K4: BULK | L4: =IF(J4="Neat","KL",IF(J4="PWD","MT","MT")) -> KL | M4: DST | N4: APAC | O4: REG-APAC-ACETYL-LM
A5: FG04 | B5: SPI-ACETYL-ACEANH-PH-98.6-NEAT-DR200_UN-MHD | C5: Specialties | D5: ACETYL | E5: Acetic Anhydride | F5: PH | G5: 98.8 | H5: 139 | I5: 8 | J5: =IF(ISNUMBER(SEARCH("-NEAT-",Sales_SKU!$B5)),"Neat",IF(ISNUMBER(SEARCH("-PWD-",Sales_SKU!$B5)),"powder","")) -> Neat | K5: DR200_UN | L5: =IF(J5="Neat","KL",IF(J5="PWD","MT","MT")) -> KL | M5: MHD | N5: DOM | O5: REG-IN-ACETYL-PH
A6: FG05 | B6: SPI-ACETYL-ACEANH-PH-98.6-NEAT-DR200_UN-MHD | C6: Specialties | D6: ACETYL | E6: Acetic Anhydride | F6: PH | G6: 98.8 | H6: 51 | I6: 8 | J6: =IF(ISNUMBER(SEARCH("-NEAT-",Sales_SKU!$B6)),"Neat",IF(ISNUMBER(SEARCH("-PWD-",Sales_SKU!$B6)),"powder","")) -> Neat | K6: DR200_UN | L6: =IF(J6="Neat","KL",IF(J6="PWD","MT","MT")) -> KL | M6: MHD | N6: EU | O6: REG-EU-ACETYL-PH
A7: FG06 | B7: SPI-ACETYL-ACEANH-PH-98.6-NEAT-DR200_UN-MHD | C7: Specialties | D7: ACETYL | E7: Acetic Anhydride | F7: PH | G7: 98.8 | H7: 64 | I7: 9 | J7: =IF(ISNUMBER(SEARCH("-NEAT-",Sales_SKU!$B7)),"Neat",IF(ISNUMBER(SEARCH("-PWD-",Sales_SKU!$B7)),"powder","")) -> Neat | K7: DR200_UN | L7: =IF(J7="Neat","KL",IF(J7="PWD","MT","MT")) -> KL | M7: MHD | N7: APAC | O7: REG-APAC-ACETYL-PH
A8: FG07 | B8: SPI-ACETYL-ACE-IND-98.4-NEAT-ISO20-LTE | C8: Specialties | D8: ACETYL | E8: Acetaldehyde | F8: IND | G8: 98.4 | H8: 345 | I8: 22 | J8: =IF(ISNUMBER(SEARCH("-NEAT-",Sales_SKU!$B8)),"Neat",IF(ISNUMBER(SEARCH("-PWD-",Sales_SKU!$B8)),"powder","")) -> Neat | K8: ISO20 | L8: =IF(J8="Neat","KL",IF(J8="PWD","MT","MT")) -> KL | M8: LTE | N8: DOM | O8: REG-IN-ACETYL-IND
A9: FG08 | B9: SPI-ACETYL-ACE-IND-98.4-NEAT-ISO20-LTE | C9: Specialties | D9: ACETYL | E9: Acetaldehyde | F9: IND | G9: 98.4 | H9: 358 | I9: 21 | J9: =IF(ISNUMBER(SEARCH("-NEAT-",Sales_SKU!$B9)),"Neat",IF(ISNUMBER(SEARCH("-PWD-",Sales_SKU!$B9)),"powder","")) -> Neat | K9: ISO20 | L9: =IF(J9="Neat","KL",IF(J9="PWD","MT","MT")) -> KL | M9: LTE | N9: EU | O9: REG-EU-ACETYL-IND
A10: FG09 | B10: SPI-ACETYL-ACE-IND-98.4-NEAT-ISO20-LTE | C10: Specialties | D10: ACETYL | E10: Acetaldehyde | F10: IND | G10: 98.4 | H10: 371 | I10: 17 | J10: =IF(ISNUMBER(SEARCH("-NEAT-",Sales_SKU!$B10)),"Neat",IF(ISNUMBER(SEARCH("-PWD-",Sales_SKU!$B10)),"powder","")) -> Neat | K10: ISO20 | L10: =IF(J10="Neat","KL",IF(J10="PWD","MT","MT")) -> KL | M10: LTE | N10: APAC | O10: REG-APAC-ACETYL-IND
A11: FG10 | B11: ESS-ACETYL-BUTACE-TECH-98.3-NEAT-DR200-DHJ | C11: Essentials | D11: ACETYL | E11: Butyl Acetate | F11: TECH | G11: 98.2 | H11: 200 | I11: 14 | J11: =IF(ISNUMBER(SEARCH("-NEAT-",Sales_SKU!$B11)),"Neat",IF(ISNUMBER(SEARCH("-PWD-",Sales_SKU!$B11)),"powder","")) -> Neat | K11: DR200 | L11: =IF(J11="Neat","KL",IF(J11="PWD","MT","MT")) -> KL | M11: DHJ | N11: DOM | O11: REG-IN-ACETYL-TECH
A12: FG11 | B12: ESS-ACETYL-BUTACE-TECH-98.3-NEAT-DR200-DHJ | C12: Essentials | D12: ACETYL | E12: Butyl Acetate | F12: TECH | G12: 98.2 | H12: 213 | I12: 14 | J12: =IF(ISNUMBER(SEARCH("-NEAT-",Sales_SKU!$B12)),"Neat",IF(ISNUMBER(SEARCH("-PWD-",Sales_SKU!$B12)),"powder","")) -> Neat | K12: DR200 | L12: =IF(J12="Neat","KL",IF(J12="PWD","MT","MT")) -> KL | M12: DHJ | N12: EU | O12: REG-EU-ACETYL-TECH
A13: FG12 | B13: ESS-ACETYL-BUTACE-TECH-98.3-NEAT-DR200-DHJ | C13: Essentials | D13: ACETYL | E13: Butyl Acetate | F13: TECH | G13: 98.2 | H13: 226 | I13: 9 | J13: =IF(ISNUMBER(SEARCH("-NEAT-",Sales_SKU!$B13)),"Neat",IF(ISNUMBER(SEARCH("-PWD-",Sales_SKU!$B13)),"powder","")) -> Neat | K13: DR200 | L13: =IF(J13="Neat","KL",IF(J13="PWD","MT","MT")) -> KL | M13: DHJ | N13: APAC | O13: REG-APAC-ACETYL-TECH
... A121: FG120 | B121: ESS-FLUORO-FLRBLK-LM-98.9-PWD-BAG25-DHJ | C121: Essentials | D121: FLUORO | E121: Fluoro Building Block | F121: LM | G121: 98.7 | H121: 236 | I121: 20 | J121: =IF(ISNUMBER(SEARCH("-NEAT-",Sales_SKU!$B121)),"Neat",IF(ISNUMBER(SEARCH("-PWD-",Sales_SKU!$B121)),"powder","")) -> powder | K121: BAG25 | L121: =IF(J121="Neat","KL",IF(J121="PWD","MT","MT")) -> MT | M121: DHJ | N121: APAC | O121: REG-APAC-FLUORO-LM

Sheet Purchase_SKU
A1: rm_id (Primary Key) | B1: SKU code (FK) | C1: rm_name | D1: rm_category | E1: rm_type | F1: uom | G1: storage_type | H1: storage_temp_c | I1: lead_time_days | J1: criticality | K1: approved_for_families | L1: primary_source_region_id | M1: notes
A2: RM0001 | B2: RM-ETH-AL-64175 | C2: Ethyl Alcohol (Ethanol) | D2: Ethyl Alcohol | E2: RAW_MATERIAL | F2: MT | G2: Tank | H2: Ambient | I2: 7 | J2: A | K2: ACETYL,DKD | L2: DOM | M2: Bulk solvent/feed; excise-controlled; illustrative
A3: RM0002 | B3: RM-AAC-GL-23011 | C3: Acetic Acid (Glacial) | D3: Acetic Acid | E3: RAW_MATERIAL | F3: MT | G3: Tank | H3: Ambient | I3: 10 | J3: A | K3: ACETYL,DKD | L3: DOM | M3: Corrosive; dedicated SS tank; illustrative
A4: RM0003 | B4: RM-BUT-NB-51720 | C4: n-Butanol | D4: Butanol | E4: RAW_MATERIAL | F4: MT | G4: Tank | H4: Ambient | I4: 14 | J4: B | K4: ACETYL | L4: APAC | M4: Flammable; used for butyl acetate; illustrative
A5: RM0004 | B5: RM-ETL-AC-11804 | C5: Ethyl Acetate (Solvent grade) | D5: Ethyl Acetate | E5: RAW_MATERIAL | F5: MT | G5: Tank | H5: Ambient | I5: 12 | J5: B | K5: ACETYL | L5: DOM | M5: Purchased solvent for blends/cleaning; illustrative
A6: RM0005 | B6: RM-MTH-AA-40218 | C6: Methacrylic Acid | D6: Methacrylic Acid | E6: RAW_MATERIAL | F6: KG | G6: Drum/IBC | H6: Ambient | I6: 28 | J6: A | K6: ACETYL | L6: EU | M6: Inhibitor present; check MEHQ ppm; illustrative
A7: RM0006 | B7: RM-ANI-LN-90355 | C7: Aniline | D7: Aniline | E7: RAW_MATERIAL | F7: KG | G7: Drum/IBC | H7: Ambient | I7: 30 | J7: A | K7: ARYLIDE | L7: DOM | M7: Toxic; COA required per batch; illustrative
A8: RM0007 | B8: RM-PCA-AN-77210 | C8: p-Chloroaniline | D8: Chloroaniline | E8: RAW_MATERIAL | F8: KG | G8: Bag | H8: Ambient | I8: 35 | J8: A | K8: ARYLIDE | L8: APAC | M8: Solid; store dry; sieve before charge; illustrative
A9: RM0008 | B9: RM-OAN-AS-55102 | C9: o-Anisidine | D9: Anisidine | E9: RAW_MATERIAL | F9: KG | G9: Drum/IBC | H9: Ambient | I9: 32 | J9: B | K9: ARYLIDE | L9: EU | M9: Light sensitive; nitrogen blanket preferred; illustrative
A10: RM0009 | B10: RM-DIK-ET-88412 | C10: Diketene | D10: Diketene | E10: RAW_MATERIAL | F10: KG | G10: Drum/IBC | H10: 2-8 | I10: 21 | J10: A | K10: DKD,ACETYL | L10: DOM | M10: Refrigerated storage; moisture sensitive; illustrative
A11: RM0010 | B11: INT-KET-INS-145120 | C11: Ketene (in-situ) | D11: Ketene | E11: INTERMEDIATE | F11: KG | G11: On-site Generation | H11: N/A | I11: 0 | J11: A | K11: DKD,ACETYL | L11: DOM | M11: Generated on demand; no inventory; illustrative
A12: RM0011 | B12: INT-DKD-INT-342781 | C12: DKD Intermediate (Crude) | D12: DKD Intermediate | E12: INTERMEDIATE | F12: KG | G12: Drum/IBC | H12: Ambient | I12: 3 | J12: B | K12: DKD | L12: DOM | M12: Internal transfer; QC release required; illustrative
A13: RM0012 | B13: INT-ARY-INT-558903 | C13: Arylide Intermediate (Wet cake) | D13: Arylide Intermediate | E13: INTERMEDIATE | F13: KG | G13: Bag | H13: Ambient | I13: 2 | J13: B | K13: ARYLIDE | L13: DOM | M13: Moist solid; process within 48h; illustrative
... A32: RM0031 | B32: RM-ETH-AL-64241 | C32: Ethyl Alcohol (Denatured) | D32: Ethyl Alcohol | E32: RAW_MATERIAL | F32: MT | G32: Tank | H32: Ambient | I32: 7 | J32: B | K32: ACETYL | L32: DOM | M32: Denatured ethanol for industrial use; non-excise; illustrative
A33: RM0032 | B33: INT-KET-674828 | C33: Diketene (Stabilized) | D33: Diketene | E33: INTERMEDIATE | F33: KG | G33: Drum/IBC | H33: 46061 | I33: 21 | J33: A | K33: DKD,ACETYL | L33: DOM | M33: Refrigerated storage; moisture sensitive; stabilized form; illustrative
A34: RM0033 | B34: INT-KET-463514 | C34: Ketene (Compressed) | D34: Ketene | E34: INTERMEDIATE | F34: KG | G34: On-site Generation | H34: N/A | I34: 0 | J34: A | K34: DKD,ACETYL | L34: DOM | M34: Generated on demand; highly reactive; no inventory hold; illustrative
A35: PKG0001 | B35: PKG-DR200 | C35: Steel Drum 200L (Standard) | D35: Steel Drums | E35: PACKAGING | F35: PCS | G35: Warehouse | H35: Ambient | I35: 10 | J35: B | K35: ACETYL,DKD,ARYLIDE,FLUORO | L35: DOM | M35: Standard 200L steel drums for non-DG products
A36: PKG0002 | B36: PKG-DR200_UN | C36: Steel Drum 200L (UN Certified) | D36: Steel Drums | E36: PACKAGING | F36: PCS | G36: Warehouse | H36: Ambient | I36: 14 | J36: A | K36: ACETYL,DKD,ARYLIDE,FLUORO | L36: DOM | M36: UN-certified drums for DG/hazmat transport; IMDG/ADR compliant
A37: PKG0003 | B37: PKG-IBC1KL | C37: IBC 1000L Composite | D37: IBC Containers | E37: PACKAGING | F37: PCS | G37: Warehouse | H37: Ambient | I37: 14 | J37: A | K37: ACETYL,DKD,ARYLIDE | L37: DOM | M37: 1000L intermediate bulk containers; reusable/reconditionable
A38: PKG0004 | B38: PKG-HDPE | C38: HDPE Container (Various) | D38: HDPE Containers | E38: PACKAGING | F38: PCS | G38: Warehouse | H38: Ambient | I38: 12 | J38: B | K38: ACETYL,DKD | L38: DOM | M38: HDPE containers for corrosive-resistant packaging
A39: PKG0005 | B39: PKG-BAG25 | C39: PP Woven Bag 25kg | D39: Bags | E39: PACKAGING | F39: PCS | G39: Warehouse | H39: Ambient | I39: 7 | J39: B | K39: ARYLIDE,FLUORO | L39: DOM | M39: 25kg woven PP bags for powder products
A40: PKG0006 | B40: PKG-FIBC | C40: FIBC Jumbo Bag 1MT | D40: IBC Containers | E40: PACKAGING | F40: PCS | G40: Warehouse | H40: Ambient | I40: 10 | J40: B | K40: ARYLIDE,FLUORO | L40: DOM | M40: 1MT bulk bags; anti-static option available
A41: PKG0007 | B41: PKG-ISO20 | C41: ISO Tank Container 20ft (Lease) | D41: ISO Tank | E41: PACKAGING | F41: DAYS | G41: Yard | H41: Ambient | I41: 5 | J41: A | K41: ACETYL,DKD | L41: EU | M41: Leased ISO tanks for bulk liquid export; heating coils available
A42: PKG0008 | B42: PKG-ISO-SWAP | C42: ISO Tank Swap Body | D42: ISO Tank | E42: PACKAGING | F42: DAYS | G42: Yard | H42: Ambient | I42: 5 | J42: B | K42: ACETYL,DKD | L42: EU | M42: Swap body tanks for intermodal transport
A43: PKG0009 | B43: PKG-FLEXI | C43: Flexitank 24KL | D43: Flexitank | E43: PACKAGING | F43: PCS | G43: Warehouse | H43: Ambient | I43: 10 | J43: B | K43: ACETYL | L43: DOM | M43: Single-use flexitanks for non-DG bulk liquids; cost-effective
A44: PKG0010 | B44: PKG-LINER | C44: Container Liner | D44: Container Liner | E44: PACKAGING | F44: PCS | G44: Warehouse | H44: Ambient | I44: 7 | J44: C | K44: ACETYL | L44: DOM | M44: Protective liners for container shipments
A45: PKG0011 | B45: PKG-LABELS | C45: Product Labels (DG/GHS) | D45: Labels & Markings | E45: PACKAGING | F45: ROLL | G45: Warehouse | H45: Ambient | I45: 5 | J45: A | K45: ACETYL,DKD,ARYLIDE,FLUORO | L45: DOM | M45: GHS-compliant hazard labels; variable data printing
... A48: PKG0014 | B48: PKG-PALLET-POOL | C48: Pooled Plastic Pallet | D48: Pallets | E48: PACKAGING | F48: TRIP | G48: Yard | H48: Ambient | I48: 3 | J48: C | K48: ACETYL,DKD,ARYLIDE,FLUORO | L48: DOM | M48: Pooled pallets; reduces capital and disposal costs

Sheet BOM_Line Item
A1: BOM Line ID (Primary Key) | B1: FG SKU Code (FK) | C1: Product Family | D1: Molecule | E1: Unit Measure of FG | F1: RM ID (FK) | G1: RM SKU Code (FK) | H1: RM Name | I1: Quantity per Unit FG | J1: UOM | K1: Yield Factor | L1: Scrap Allowance (%) | M1: Effective From | N1: Effective To | O1: Status | P1: Notes
A2: BOM00001 | B2: ESS-ACETYL-ETHACE-LM-98.5-NEAT-BULK-DST | C2: ACETYL | D2: Ethyl Acetate | E2: ="1 "&IFERROR(_xlfn.XLOOKUP(B2,Sales_SKU!$B$2:$B$121,Sales_SKU!$L$2:$L$121,"MT"),"MT") -> 1 KL | F2: RM0001 | G2: RM-ETH-AL-64175 | H2: Ethyl Alcohol (Ethanol) | I2: =IF(RIGHT(E2,2)="KL",0.52*0.9,0.52) -> 0.468 | J2: MT | K2: 0.98 | L2: 0.02 | M2: 46023 | O2: Active | P2: Primary ethanol feed (esterification)
A3: BOM00002 | B3: ESS-ACETYL-ETHACE-LM-98.5-NEAT-BULK-DST | C3: ACETYL | D3: Ethyl Acetate | E3: ="1 "&IFERROR(_xlfn.XLOOKUP(B3,Sales_SKU!$B$2:$B$121,Sales_SKU!$L$2:$L$121,"MT"),"MT") -> 1 KL | F3: RM0002 | G3: RM-AAC-GL-23011 | H3: Acetic Acid (Glacial) | I3: =IF(RIGHT(E3,2)="KL",0.68*0.9,0.68) -> 0.612 | J3: MT | K3: 0.98 | L3: 0.02 | M3: 46023 | O3: Active | P3: Glacial acetic acid for esterification
A4: BOM00003 | B4: ESS-ACETYL-ETHACE-LM-98.5-NEAT-BULK-DST | C4: ACETYL | D4: Ethyl Acetate | E4: ="1 "&IFERROR(_xlfn.XLOOKUP(B4,Sales_SKU!$B$2:$B$121,Sales_SKU!$L$2:$L$121,"MT"),"MT") -> 1 KL | F4: RM0017 | G4: RM-ACN-SV-33120 | H4: Acetonitrile | I4: =IF(RIGHT(E4,2)="KL",0.008*0.9,0.008) -> 0.0072 | J4: KG | K4: 0.98 | L4: 0.02 | M4: 46023 | O4: Active | P4: Sulfuric acid catalyst
A5: BOM00004 | B5: SPI-ACETYL-ACEANH-PH-98.6-NEAT-DR200_UN-MHD | C5: ACETYL | D5: Acetic Anhydride | E5: ="1 "&IFERROR(_xlfn.XLOOKUP(B5,Sales_SKU!$B$2:$B$121,Sales_SKU!$L$2:$L$121,"MT"),"MT") -> 1 KL | F5: RM0002 | G5: RM-AAC-GL-23011 | H5: Acetic Acid (Glacial) | I5: =IF(RIGHT(E5,2)="KL",1.18*0.9,1.18) -> 1.062 | J5: MT | K5: 0.98 | L5: 0.02 | M5: 46023 | O5: Active | P5: Primary acetic acid feed (dehydration)
A6: BOM00005 | B6: SPI-ACETYL-ACEANH-PH-98.6-NEAT-DR200_UN-MHD | C6: ACETYL | D6: Acetic Anhydride | E6: ="1 "&IFERROR(_xlfn.XLOOKUP(B6,Sales_SKU!$B$2:$B$121,Sales_SKU!$L$2:$L$121,"MT"),"MT") -> 1 KL | F6: RM0020 | G6: RM-PDH-CB-61302 | H6: Palladium on Carbon (5%) | I6: =IF(RIGHT(E6,2)="KL",0.003*0.9,0.003) -> 0.0027 | J6: KG | K6: 0.98 | L6: 0.02 | M6: 46023 | O6: Active | P6: Catalyst for dehydration process
A7: BOM00006 | B7: SPI-ACETYL-ACEANH-PH-98.6-NEAT-DR200_UN-MHD | C7: ACETYL | D7: Acetic Anhydride | E7: ="1 "&IFERROR(_xlfn.XLOOKUP(B7,Sales_SKU!$B$2:$B$121,Sales_SKU!$L$2:$L$121,"MT"),"MT") -> 1 KL | F7: RM0036 | G7: PKG-DR200_UN | H7: Steel Drum 200L (UN Certified) | I7: =IF(RIGHT(E7,2)="KL",5*0.9,5) -> 4.5 | J7: PCS | K7: 0.99 | L7: 0.01 | M7: 46023 | O7: Active | P7: UN-certified drums for DG
A8: BOM00007 | B8: SPI-ACETYL-ACEANH-PH-98.6-NEAT-DR200_UN-MHD | C8: ACETYL | D8: Acetic Anhydride | E8: ="1 "&IFERROR(_xlfn.XLOOKUP(B8,Sales_SKU!$B$2:$B$121,Sales_SKU!$L$2:$L$121,"MT"),"MT") -> 1 KL | F8: RM0043 | G8: PKG-LABELS | H8: Product Labels (DG/GHS) | I8: =IF(RIGHT(E8,2)="KL",5*0.9,5) -> 4.5 | J8: SET | K8: 0.99 | L8: 0.01 | M8: 46023 | O8: Active | P8: DG/GHS labels (1 per drum)
A9: BOM00008 | B9: SPI-ACETYL-ACEANH-PH-98.6-NEAT-DR200_UN-MHD | C9: ACETYL | D9: Acetic Anhydride | E9: ="1 "&IFERROR(_xlfn.XLOOKUP(B9,Sales_SKU!$B$2:$B$121,Sales_SKU!$L$2:$L$121,"MT"),"MT") -> 1 KL | F9: RM0044 | G9: PKG-DG-MARKS | H9: DG Placards & Markings | I9: =IF(RIGHT(E9,2)="KL",0.2*0.9,0.2) -> 0.18 | J9: SET | K9: 0.99 | L9: 0.01 | M9: 46023 | O9: Active | P9: DG placards (per pallet)
A10: BOM00009 | B10: SPI-ACETYL-ACEANH-PH-98.6-NEAT-DR200_UN-MHD | C10: ACETYL | D10: Acetic Anhydride | E10: ="1 "&IFERROR(_xlfn.XLOOKUP(B10,Sales_SKU!$B$2:$B$121,Sales_SKU!$L$2:$L$121,"MT"),"MT") -> 1 KL | F10: RM0046 | G10: PKG-PALLET | H10: Wooden Pallet (ISPM-15) | I10: =IF(RIGHT(E10,2)="KL",1.25*0.9,1.25) -> 1.125 | J10: PCS | K10: 0.99 | L10: 0.01 | M10: 46023 | O10: Active | P10: Wooden pallet (4 drums per pallet)
A11: BOM00010 | B11: SPI-ACETYL-ACE-IND-98.4-NEAT-ISO20-LTE | C11: ACETYL | D11: Acetaldehyde | E11: ="1 "&IFERROR(_xlfn.XLOOKUP(B11,Sales_SKU!$B$2:$B$121,Sales_SKU!$L$2:$L$121,"MT"),"MT") -> 1 KL | F11: RM0001 | G11: RM-ETH-AL-64175 | H11: Ethyl Alcohol (Ethanol) | I11: =IF(RIGHT(E11,2)="KL",1.05*0.9,1.05) -> 0.945 | J11: MT | K11: 0.98 | L11: 0.02 | M11: 46023 | O11: Active | P11: Ethanol for catalytic oxidation
A12: BOM00011 | B12: SPI-ACETYL-ACE-IND-98.4-NEAT-ISO20-LTE | C12: ACETYL | D12: Acetaldehyde | E12: ="1 "&IFERROR(_xlfn.XLOOKUP(B12,Sales_SKU!$B$2:$B$121,Sales_SKU!$L$2:$L$121,"MT"),"MT") -> 1 KL | F12: RM0020 | G12: RM-PDH-CB-61302 | H12: Palladium on Carbon (5%) | I12: =IF(RIGHT(E12,2)="KL",0.002*0.9,0.002) -> 0.0018 | J12: KG | K12: 0.98 | L12: 0.02 | M12: 46023 | O12: Active | P12: Oxidation catalyst
A13: BOM00012 | B13: SPI-ACETYL-ACE-IND-98.4-NEAT-ISO20-LTE | C13: ACETYL | D13: Acetaldehyde | E13: ="1 "&IFERROR(_xlfn.XLOOKUP(B13,Sales_SKU!$B$2:$B$121,Sales_SKU!$L$2:$L$121,"MT"),"MT") -> 1 KL | F13: RM0039 | G13: PKG-ISO20 | H13: ISO Tank Container 20ft | I13: =IF(RIGHT(E13,2)="KL",0.05*0.9,0.05) -> 0.045 | J13: TRIP | K13: 0.99 | L13: 0.01 | M13: 46023 | O13: Active | P13: ISO tank (20ft, ~20MT capacity)
A14: BOM00013 | B14: ESS-ACETYL-BUTACE-TECH-98.3-NEAT-DR200-DHJ | C14: ACETYL | D14: Butyl Acetate | E14: ="1 "&IFERROR(_xlfn.XLOOKUP(B14,Sales_SKU!$B$2:$B$121,Sales_SKU!$L$2:$L$121,"MT"),"MT") -> 1 KL | F14: RM0003 | G14: RM-BUT-NB-51720 | H14: n-Butanol | I14: =IF(RIGHT(E14,2)="KL",0.64*0.9,0.64) -> 0.576 | J14: MT | K14: 0.98 | L14: 0.02 | M14: 46023 | O14: Active | P14: n-Butanol primary alcohol
A15: BOM00014 | B15: ESS-ACETYL-BUTACE-TECH-98.3-NEAT-DR200-DHJ | C15: ACETYL | D15: Butyl Acetate | E15: ="1 "&IFERROR(_xlfn.XLOOKUP(B15,Sales_SKU!$B$2:$B$121,Sales_SKU!$L$2:$L$121,"MT"),"MT") -> 1 KL | F15: RM0002 | G15: RM-AAC-GL-23011 | H15: Acetic Acid (Glacial) | I15: =IF(RIGHT(E15,2)="KL",0.52*0.9,0.52) -> 0.468 | J15: MT | K15: 0.98 | L15: 0.02 | M15: 46023 | O15: Active | P15: Acetic acid for esterification
A16: BOM00015 | B16: ESS-ACETYL-BUTACE-TECH-98.3-NEAT-DR200-DHJ | C16: ACETYL | D16: Butyl Acetate | E16: ="1 "&IFERROR(_xlfn.XLOOKUP(B16,Sales_SKU!$B$2:$B$121,Sales_SKU!$L$2:$L$121,"MT"),"MT") -> 1 KL | F16: RM0017 | G16: RM-ACN-SV-33120 | H16: Acetonitrile | I16: =IF(RIGHT(E16,2)="KL",0.012*0.9,0.012) -> 0.0108 | J16: KG | K16: 0.98 | L16: 0.02 | M16: 46023 | O16: Active | P16: Sulfuric acid catalyst
A17: BOM00016 | B17: ESS-ACETYL-BUTACE-TECH-98.3-NEAT-DR200-DHJ | C17: ACETYL | D17: Butyl Acetate | E17: ="1 "&IFERROR(_xlfn.XLOOKUP(B17,Sales_SKU!$B$2:$B$121,Sales_SKU!$L$2:$L$121,"MT"),"MT") -> 1 KL | F17: RM0035 | G17: PKG-DR200 | H17: Steel Drum 200L (Standard) | I17: =IF(RIGHT(E17,2)="KL",5*0.9,5) -> 4.5 | J17: PCS | K17: 0.99 | L17: 0.01 | M17: 46023 | O17: Active | P17: 200L drums (5 per MT)
A18: BOM00017 | B18: ESS-ACETYL-BUTACE-TECH-98.3-NEAT-DR200-DHJ | C18: ACETYL | D18: Butyl Acetate | E18: ="1 "&IFERROR(_xlfn.XLOOKUP(B18,Sales_SKU!$B$2:$B$121,Sales_SKU!$L$2:$L$121,"MT"),"MT") -> 1 KL | F18: RM0046 | G18: PKG-PALLET | H18: Wooden Pallet (ISPM-15) | I18: =IF(RIGHT(E18,2)="KL",1.25*0.9,1.25) -> 1.125 | J18: PCS | K18: 0.99 | L18: 0.01 | M18: 46023 | O18: Active | P18: Wooden pallet (4 drums per pallet)
A19: BOM00018 | B19: ESS-ACETYL-MAA-LM-98.4-NEAT-IBC1KL-DST | C19: ACETYL | D19: Methyl Acetoacetate | E19: ="1 "&IFERROR(_xlfn.XLOOKUP(B19,Sales_SKU!$B$2:$B$121,Sales_SKU!$L$2:$L$121,"MT"),"MT") -> 1 KL | F19: RM0009 | G19: RM-DIK-ET-88412 | H19: Diketene | I19: =IF(RIGHT(E19,2)="KL",0.85*0.9,0.85) -> 0.765 | J19: KG | K19: 0.98 | L19: 0.02 | M19: 46023 | O19: Active | P19: Diketene for acetoacetylation
A20: BOM00019 | B20: ESS-ACETYL-MAA-LM-98.4-NEAT-IBC1KL-DST | C20: ACETYL | D20: Methyl Acetoacetate | E20: ="1 "&IFERROR(_xlfn.XLOOKUP(B20,Sales_SKU!$B$2:$B$121,Sales_SKU!$L$2:$L$121,"MT"),"MT") -> 1 KL | F20: RM0001 | G20: RM-ETH-AL-64175 | H20: Ethyl Alcohol (Ethanol) | I20: =IF(RIGHT(E20,2)="KL",0.38*0.9,0.38) -> 0.342 | J20: MT | K20: 0.98 | L20: 0.02 | M20: 46023 | O20: Active | P20: Alcohol for ester formation
A21: BOM00020 | B21: ESS-ACETYL-MAA-LM-98.4-NEAT-IBC1KL-DST | C21: ACETYL | D21: Methyl Acetoacetate | E21: ="1 "&IFERROR(_xlfn.XLOOKUP(B21,Sales_SKU!$B$2:$B$121,Sales_SKU!$L$2:$L$121,"MT"),"MT") -> 1 KL | F21: RM0020 | G21: RM-PDH-CB-61302 | H21: Palladium on Carbon (5%) | I21: =IF(RIGHT(E21,2)="KL",0.002*0.9,0.002) -> 0.0018 | J21: KG | K21: 0.98 | L21: 0.02 | M21: 46023 | O21: Active | P21: Process catalyst
A22: BOM00021 | B22: ESS-ACETYL-MAA-LM-98.4-NEAT-IBC1KL-DST | C22: ACETYL | D22: Methyl Acetoacetate | E22: ="1 "&IFERROR(_xlfn.XLOOKUP(B22,Sales_SKU!$B$2:$B$121,Sales_SKU!$L$2:$L$121,"MT"),"MT") -> 1 KL | F22: RM0037 | G22: PKG-IBC1KL | H22: IBC 1000L Composite | I22: =IF(RIGHT(E22,2)="KL",1*0.9,1) -> 0.9 | J22: PCS | K22: 0.99 | L22: 0.01 | M22: 46023 | O22: Active | P22: 1000L IBC (~1 MT capacity)
A23: BOM00022 | B23: SPI-ACETYL-EAA-IND-99.2-NEAT-DR200-MHD | C23: ACETYL | D23: Ethyl Acetoacetate | E23: ="1 "&IFERROR(_xlfn.XLOOKUP(B23,Sales_SKU!$B$2:$B$121,Sales_SKU!$L$2:$L$121,"MT"),"MT") -> 1 KL | F23: RM0009 | G23: RM-DIK-ET-88412 | H23: Diketene | I23: =IF(RIGHT(E23,2)="KL",0.65*0.9,0.65) -> 0.585 | J23: KG | K23: 0.98 | L23: 0.02 | M23: 46023 | O23: Active | P23: Diketene derivative source
A24: BOM00023 | B24: SPI-ACETYL-EAA-IND-99.2-NEAT-DR200-MHD | C24: ACETYL | D24: Ethyl Acetoacetate | E24: ="1 "&IFERROR(_xlfn.XLOOKUP(B24,Sales_SKU!$B$2:$B$121,Sales_SKU!$L$2:$L$121,"MT"),"MT") -> 1 KL | F24: RM0001 | G24: RM-ETH-AL-64175 | H24: Ethyl Alcohol (Ethanol) | I24: =IF(RIGHT(E24,2)="KL",0.36*0.9,0.36) -> 0.324 | J24: MT | K24: 0.98 | L24: 0.02 | M24: 46023 | O24: Active | P24: Ethanol for esterification
A25: BOM00024 | B25: SPI-ACETYL-EAA-IND-99.2-NEAT-DR200-MHD | C25: ACETYL | D25: Ethyl Acetoacetate | E25: ="1 "&IFERROR(_xlfn.XLOOKUP(B25,Sales_SKU!$B$2:$B$121,Sales_SKU!$L$2:$L$121,"MT"),"MT") -> 1 KL | F25: RM0020 | G25: RM-PDH-CB-61302 | H25: Palladium on Carbon (5%) | I25: =IF(RIGHT(E25,2)="KL",0.002*0.9,0.002) -> 0.0018 | J25: KG | K25: 0.98 | L25: 0.02 | M25: 46023 | O25: Active | P25: Catalyst
A26: BOM00025 | B26: SPI-ACETYL-EAA-IND-99.2-NEAT-DR200-MHD | C26: ACETYL | D26: Ethyl Acetoacetate | E26: ="1 "&IFERROR(_xlfn.XLOOKUP(B26,Sales_SKU!$B$2:$B$121,Sales_SKU!$L$2:$L$121,"MT"),"MT") -> 1 KL | F26: RM0035 | G26: PKG-DR200 | H26: Steel Drum 200L (Standard) | I26: =IF(RIGHT(E26,2)="KL",5*0.9,5) -> 4.5 | J26: PCS | K26: 0.99 | L26: 0.01 | M26: 46023 | O26: Active | P26: 200L drums (5 per MT)
A27: BOM00026 | B27: SPI-ACETYL-EAA-IND-99.2-NEAT-DR200-MHD | C27: ACETYL | D27: Ethyl Acetoacetate | E27: ="1 "&IFERROR(_xlfn.XLOOKUP(B27,Sales_SKU!$B$2:$B$121,Sales_SKU!$L$2:$L$121,"MT"),"MT") -> 1 KL | F27: RM0046 | G27: PKG-PALLET | H27: Wooden Pallet (ISPM-15) | I27: =IF(RIGHT(E27,2)="KL",1.25*0.9,1.25) -> 1.125 | J27: PCS | K27: 0.99 | L27: 0.01 | M27: 46023 | O27: Active | P27: Wooden pallet (4 drums per pallet)
A28: BOM00027 | B28: ESS-ACETYL-AAEM-TECH-98.8-NEAT-BULK-LTE | C28: ACETYL | D28: AAEM (Acetoacetoxyethyl Methacrylate) | E28: ="1 "&IFERROR(_xlfn.XLOOKUP(B28,Sales_SKU!$B$2:$B$121,Sales_SKU!$L$2:$L$121,"MT"),"MT") -> 1 KL | F28: RM0005 | G28: RM-MTH-AA-40218 | H28: Methacrylic Acid | I28: =IF(RIGHT(E28,2)="KL",0.67*0.9,0.67) -> 0.603 | J28: KG | K28: 0.98 | L28: 0.02 | M28: 46023 | O28: Active | P28: Methacrylic acid for acrylate synthesis
A29: BOM00028 | B29: ESS-ACETYL-AAEM-TECH-98.8-NEAT-BULK-LTE | C29: ACETYL | D29: AAEM (Acetoacetoxyethyl Methacrylate) | E29: ="1 "&IFERROR(_xlfn.XLOOKUP(B29,Sales_SKU!$B$2:$B$121,Sales_SKU!$L$2:$L$121,"MT"),"MT") -> 1 KL | F29: RM0009 | G29: RM-DIK-ET-88412 | H29: Diketene | I29: =IF(RIGHT(E29,2)="KL",0.55*0.9,0.55) -> 0.495 | J29: KG | K29: 0.98 | L29: 0.02 | M29: 46023 | O29: Active | P29: Diketene for acetoacetyl group
A30: BOM00029 | B30: ESS-ACETYL-AAEM-TECH-98.8-NEAT-BULK-LTE | C30: ACETYL | D30: AAEM (Acetoacetoxyethyl Methacrylate) | E30: ="1 "&IFERROR(_xlfn.XLOOKUP(B30,Sales_SKU!$B$2:$B$121,Sales_SKU!$L$2:$L$121,"MT"),"MT") -> 1 KL | F30: RM0001 | G30: RM-ETH-AL-64175 | H30: Ethyl Alcohol (Ethanol) | I30: =IF(RIGHT(E30,2)="KL",0.22*0.9,0.22) -> 0.198 | J30: MT | K30: 0.98 | L30: 0.02 | M30: 46023 | O30: Active | P30: Ethanol solvent/reactant
A31: BOM00030 | B31: ESS-ACETYL-AAEM-TECH-98.8-NEAT-BULK-LTE | C31: ACETYL | D31: AAEM (Acetoacetoxyethyl Methacrylate) | E31: ="1 "&IFERROR(_xlfn.XLOOKUP(B31,Sales_SKU!$B$2:$B$121,Sales_SKU!$L$2:$L$121,"MT"),"MT") -> 1 KL | F31: RM0020 | G31: RM-PDH-CB-61302 | H31: Palladium on Carbon (5%) | I31: =IF(RIGHT(E31,2)="KL",0.003*0.9,0.003) -> 0.0027 | J31: KG | K31: 0.98 | L31: 0.02 | M31: 46023 | O31: Active | P31: Process catalyst
A32: BOM00031 | B32: ESS-DKD-DKDINT-INK-99.6-NEAT-DR200-DHJ | C32: DKD | D32: DKD Intermediate | E32: ="1 "&IFERROR(_xlfn.XLOOKUP(B32,Sales_SKU!$B$2:$B$121,Sales_SKU!$L$2:$L$121,"MT"),"MT") -> 1 KL | F32: RM0009 | G32: RM-DIK-ET-88412 | H32: Diketene | I32: =IF(RIGHT(E32,2)="KL",0.92*0.9,0.92) -> 0.828 | J32: KG | K32: 0.98 | L32: 0.02 | M32: 46023 | O32: Active | P32: Primary diketene feed
A33: BOM00032 | B33: ESS-DKD-DKDINT-INK-99.6-NEAT-DR200-DHJ | C33: DKD | D33: DKD Intermediate | E33: ="1 "&IFERROR(_xlfn.XLOOKUP(B33,Sales_SKU!$B$2:$B$121,Sales_SKU!$L$2:$L$121,"MT"),"MT") -> 1 KL | F33: RM0001 | G33: RM-ETH-AL-64175 | H33: Ethyl Alcohol (Ethanol) | I33: =IF(RIGHT(E33,2)="KL",0.28*0.9,0.28) -> 0.252 | J33: MT | K33: 0.98 | L33: 0.02 | M33: 46023 | O33: Active | P33: Ethanol process solvent
A34: BOM00033 | B34: ESS-DKD-DKDINT-INK-99.6-NEAT-DR200-DHJ | C34: DKD | D34: DKD Intermediate | E34: ="1 "&IFERROR(_xlfn.XLOOKUP(B34,Sales_SKU!$B$2:$B$121,Sales_SKU!$L$2:$L$121,"MT"),"MT") -> 1 KL | F34: RM0002 | G34: RM-AAC-GL-23011 | H34: Acetic Acid (Glacial) | I34: =IF(RIGHT(E34,2)="KL",0.15*0.9,0.15) -> 0.135 | J34: MT | K34: 0.98 | L34: 0.02 | M34: 46023 | O34: Active | P34: Acetic acid for process
A35: BOM00034 | B35: ESS-DKD-DKDINT-INK-99.6-NEAT-DR200-DHJ | C35: DKD | D35: DKD Intermediate | E35: ="1 "&IFERROR(_xlfn.XLOOKUP(B35,Sales_SKU!$B$2:$B$121,Sales_SKU!$L$2:$L$121,"MT"),"MT") -> 1 KL | F35: RM0035 | G35: PKG-DR200 | H35: Steel Drum 200L (Standard) | I35: =IF(RIGHT(E35,2)="KL",5*0.9,5) -> 4.5 | J35: PCS | K35: 0.99 | L35: 0.01 | M35: 46023 | O35: Active | P35: 200L drums (5 per MT)
A36: BOM00035 | B36: ESS-DKD-DKDINT-INK-99.6-NEAT-DR200-DHJ | C36: DKD | D36: DKD Intermediate | E36: ="1 "&IFERROR(_xlfn.XLOOKUP(B36,Sales_SKU!$B$2:$B$121,Sales_SKU!$L$2:$L$121,"MT"),"MT") -> 1 KL | F36: RM0046 | G36: PKG-PALLET | H36: Wooden Pallet (ISPM-15) | I36: =IF(RIGHT(E36,2)="KL",1.25*0.9,1.25) -> 1.125 | J36: PCS | K36: 0.99 | L36: 0.01 | M36: 46023 | O36: Active | P36: Wooden pallet (4 drums per pallet)
A37: BOM00036 | B37: ESS-ARYLIDE-ARYINT-IND-99.9-PWD-BAG25-DST | C37: ARYLIDE | D37: Arylide Intermediate | E37: ="1 "&IFERROR(_xlfn.XLOOKUP(B37,Sales_SKU!$B$2:$B$121,Sales_SKU!$L$2:$L$121,"MT"),"MT") -> 1 MT | F37: RM0006 | G37: RM-ANI-LN-90355 | H37: Aniline | I37: =IF(RIGHT(E37,2)="KL",0.72*0.9,0.72) -> 0.72 | J37: KG | K37: 0.98 | L37: 0.02 | M37: 46023 | O37: Active | P37: Aniline primary aromatic amine
A38: BOM00037 | B38: ESS-ARYLIDE-ARYINT-IND-99.9-PWD-BAG25-DST | C38: ARYLIDE | D38: Arylide Intermediate | E38: ="1 "&IFERROR(_xlfn.XLOOKUP(B38,Sales_SKU!$B$2:$B$121,Sales_SKU!$L$2:$L$121,"MT"),"MT") -> 1 MT | F38: RM0007 | G38: RM-PCA-AN-77210 | H38: p-Chloroaniline | I38: =IF(RIGHT(E38,2)="KL",0.35*0.9,0.35) -> 0.35 | J38: KG | K38: 0.98 | L38: 0.02 | M38: 46023 | O38: Active | P38: p-Chloroaniline for coupling
A39: BOM00038 | B39: ESS-ARYLIDE-ARYINT-IND-99.9-PWD-BAG25-DST | C39: ARYLIDE | D39: Arylide Intermediate | E39: ="1 "&IFERROR(_xlfn.XLOOKUP(B39,Sales_SKU!$B$2:$B$121,Sales_SKU!$L$2:$L$121,"MT"),"MT") -> 1 MT | F39: RM0008 | G39: RM-OAN-AS-55102 | H39: o-Anisidine | I39: =IF(RIGHT(E39,2)="KL",0.18*0.9,0.18) -> 0.18 | J39: KG | K39: 0.98 | L39: 0.02 | M39: 46023 | O39: Active | P39: o-Anisidine methoxy derivative
A40: BOM00039 | B40: ESS-ARYLIDE-ARYINT-IND-99.9-PWD-BAG25-DST | C40: ARYLIDE | D40: Arylide Intermediate | E40: ="1 "&IFERROR(_xlfn.XLOOKUP(B40,Sales_SKU!$B$2:$B$121,Sales_SKU!$L$2:$L$121,"MT"),"MT") -> 1 MT | F40: RM0002 | G40: RM-AAC-GL-23011 | H40: Acetic Acid (Glacial) | I40: =IF(RIGHT(E40,2)="KL",0.25*0.9,0.25) -> 0.25 | J40: MT | K40: 0.98 | L40: 0.02 | M40: 46023 | O40: Active | P40: Acetic acid for acetylation step
...

Sheet Regions
A1: region_id (Primary Key) | B1: region_name | C1: type | D1: active | E1: notes
A2: DOM | B2: India (Domestic) | C2: COUNTRY | D2: TRUE | E2: Domestic sales; GST invoicing; standard road lanes.
A3: EU | B3: European Union | C3: BLOC | D3: TRUE | E3: REACH/CLP compliance; SDS in local languages; DG-capable sea lanes.
A4: AMER | B4: Americas | C4: REGION | D4: TRUE | E4: US/LatAm exports; TSCA alignment; longer lead times via ocean freight.
A5: APAC | B5: Asia Pacific | C5: REGION | D5: TRUE | E5: APAC export hub; varied local registrations; mixed sea/road lanes.
A6: MEA | B6: Middle East & Africa | C6: REGION | D6: TRUE | E6: Often DG documentation required; bank LC common; temperature exposure risk.
A7: ROW | B7: Rest of World | C7: REGION | D7: TRUE | E7: Catch-all region for ad-hoc exports; validate local regulatory needs per shipment.

Sheet Countries
A1: country_id (Primary Key) | B1: country_name | C1: type | D1: iso_code | E1: region_id (FK) | F1: active | G1: notes
A2: IND | B2: India | C2: COUNTRY | D2: IN | E2: DOM | F2: TRUE | G2: Home market; GST/road lanes.
A3: DEU | B3: Germany | C3: COUNTRY | D3: DE | E3: EU | F3: TRUE | G3: EU; REACH/CLP aligned.
A4: FRA | B4: France | C4: COUNTRY | D4: FR | E4: EU | F4: TRUE | G4: EU; DG documentation common.
A5: ITA | B5: Italy | C5: COUNTRY | D5: IT | E5: EU | F5: TRUE | G5: EU; port lead times vary.
A6: ESP | B6: Spain | C6: COUNTRY | D6: ES | E6: EU | F6: TRUE | G6: EU; distributor network.
A7: NLD | B7: Netherlands | C7: COUNTRY | D7: NL | E7: EU | F7: TRUE | G7: EU hub; Rotterdam.
A8: BEL | B8: Belgium | C8: COUNTRY | D8: BE | E8: EU | F8: TRUE | G8: EU chemicals; strict SDS.
A9: POL | B9: Poland | C9: COUNTRY | D9: PL | E9: EU | F9: TRUE | G9: EU; growing demand.
A10: SWE | B10: Sweden | C10: COUNTRY | D10: SE | E10: EU | F10: TRUE | G10: EU; DG sea lanes.
A11: DNK | B11: Denmark | C11: COUNTRY | D11: DK | E11: EU | F11: TRUE | G11: EU; DG sea lanes.
A12: AUT | B12: Austria | C12: COUNTRY | D12: AT | E12: EU | F12: TRUE | G12: EU; inland trucking.
A13: CZE | B13: Czech Republic | C13: COUNTRY | D13: CZ | E13: EU | F13: TRUE | G13: EU; labeling compliance.
... A53: IRN | B53: Iran | C53: COUNTRY | D53: IR | E53: MEA | F53: FALSE | G53: Restricted market; illustrative inactive.

Sheet Customers
A1: customer_id (Primary Key) | B1: customer_name | C1: customer_type | D1: industry | E1: industry_code | F1: customer_region_id (FK-style) | G1: country_iso (FK) | H1: city | I1: currency | J1: channel | K1: risk_rating | L1: status | M1: gst_vat_id | N1: key_account_manager | O1: created_date
A2: CUS0001 | B2: GreenField Pharma GmbH | C2: B2B | D2: Pharmaceuticals | E2: PHARMA | F2: DOM | G2: IN | H2: Ahmedabad | I2: INR | J2: Direct | K2: C | L2: Active | M2: TAX-IN-499676 | N2: Team-Strategic | O2: 45994
A3: CUS0002 | B3: Keystone Pigments Co. Ltd | C3: B2B | D3: Adhesives | E3: ADH | F3: APAC | G3: CN | H3: Shanghai | I3: CNY | J3: Distributor | K3: A | L3: Active | M3: TAX-CN-943121 | N3: Team-Intl | O3: 46191
A4: CUS0003 | B4: Aurum Agro S.A. | C4: B2B | D4: Industrial Solvents | E4: SOLV | F4: DOM | G4: IN | H4: Mumbai | I4: INR | J4: Distributor | K4: C | L4: Active | M4: TAX-IN-696397 | N4: Team-South | O4: 46070
A5: CUS0004 | B5: BluePeak Agro Ltd | C5: B2B | D5: Pigments | E5: PIGM | F5: AMER | G5: US | H5: Newark | I5: USD | J5: Distributor | K5: B | L5: Active | M5: TAX-US-215769 | N5: Team-Intl | O5: 45589
A6: CUS0005 | B6: Keystone Coatings S.A. | C6: B2B | D6: Inks & Coatings | E6: INKS | F6: DOM | G6: IN | H6: Gurgaon | I6: INR | J6: Distributor | K6: B | L6: Active | M6: TAX-IN-979970 | N6: Team-West | O6: 45404
A7: CUS0006 | B7: Sapphire Pharma NV | C7: B2B | D7: Industrial Solvents | E7: SOLV | F7: APAC | G7: CN | H7: Shenzhen | I7: CNY | J7: Direct | K7: A | L7: Active | M7: TAX-CN-490679 | N7: Team-Strategic | O7: 45521
A8: CUS0007 | B8: Sterling Solvents GmbH | C8: B2B | D8: Adhesives | E8: ADH | F8: DOM | G8: IN | H8: Gurgaon | I8: INR | J8: Direct | K8: A | L8: Active | M8: TAX-IN-987820 | N8: Team-South | O8: 45758
A9: CUS0008 | B9: Nimbus Pigments S.A. | C9: B2B | D9: Agrochemicals | E9: AGRO | F9: AMER | G9: US | H9: Newark | I9: USD | J9: Direct | K9: B | L9: Active | M9: TAX-US-840961 | N9: Team-Intl | O9: 46292
A10: CUS0009 | B10: Silverline Pharma Inc. | C10: B2B | D10: Packaging | E10: PKG | F10: DOM | G10: IN | H10: Ahmedabad | I10: INR | J10: Direct | K10: B | L10: Active | M10: TAX-IN-700729 | N10: Team-South | O10: 45897
A11: CUS0010 | B11: Keystone Coatings Co. Ltd | C11: B2B | D11: Inks & Coatings | E11: INKS | F11: EU | G11: FR | H11: Lyon | I11: EUR | J11: Distributor | K11: B | L11: Active | M11: TAX-FR-255209 | N11: Team-Intl | O11: 45884
A12: CUS0011 | B12: Nimbus Packaging NV | C12: B2B | D12: Pigments | E12: PIGM | F12: EU | G12: SE | H12: Barcelona | I12: EUR | J12: Distributor | K12: A | L12: Active | M12: TAX-SE-766346 | N12: Team-Intl | O12: 46356
A13: CUS0012 | B13: Sterling Agro LLP | C13: B2B | D13: Adhesives | E13: ADH | F13: DOM | G13: IN | H13: Chennai | I13: INR | J13: Distributor | K13: B | L13: Prospect | M13: TAX-IN-731425 | N13: Team-Strategic | O13: 46281
... A101: CUS0100 | B101: Atlas Pigments LLP | C101: B2B | D101: Pigments | E101: PIGM | F101: EU | G101: DE | H101: Warsaw | I101: EUR | J101: Direct | K101: C | L101: Active | M101: TAX-DE-234001 | N101: Team-Intl | O101: 46341

Sheet SLA Profiles
A1: sla_id (Primary Key) | B1: sla_name | C1: scope_region_id (FK) | D1: applicable_channels | E1: applicable_families | F1: incoterms_scope | G1: service_window_cutoff_local | H1: service_days | I1: dispatch_lead_time_days (min) | J1: dispatch_lead_time_days (max) | K1: Handover at | L1: delivery_window_days (min) | M1: delivery_window_days (max) | N1: otif_target_pct | O1: ot_time_tolerance | P1: in_full_target_pct | Q1: fill_rate_target_pct | R1: backorder_resolution_days | S1: quote_tat_hours | T1: order_ack_tat_hours | U1: documentation_requirements | V1: documentation_accuracy_pct | W1: pod_submission_hours | X1: claims_response_business_days | Y1: claims_closure_business_days | Z1: temperature_control | AA1: dg_class_handling | AB1: min_order_quantity | AC1: packaging_constraints | AD1: penalty_credit_logic | AE1: review_frequency | AF1: effective_from | AG1: effective_to | AH1: status
A2: SLA_STD_DOM_T1 | B2: Domestic Standard T1 (Bulk Liquids) | C2: DOM | D2: Direct,Distributor | E2: ACETYL,DKD | F2: EXW/FCA | G2: 14:00 | H2: Mon-Sat | I2: 1 | J2: 2 | K2: Plant gate | L2: 1 | M2: 3 | N2: 94 | O2: +/-1 day | P2: 97 | Q2: 96 | R2: 5 | S2: 8 | T2: 4 | U2: COA,Invoice,Ewaybill | V2: 99.5 | W2: 48 | X2: 3 | Y2: 10 | Z2: Ambient | AA2: DG allowed (where applicable) | AB2: 2000 KG | AC2: BULK,ISO20,IBC1KL | AD2: 1% credit if OTIF < target (monthly) on eligible orders | AE2: Quarterly | AF2: 2026-01-01 | AH2: Active
A3: SLA_STD_DOM_T2 | B3: Domestic Priority T2 (Drums/IBCs) | C3: DOM | D3: Direct,Distributor | E3: ACETYL,DKD,ARYLIDE | F3: EXW/FCA | G3: 16:00 | H3: Mon-Sat | I3: 0 | J3: 1 | K3: Plant gate | L3: 1 | M3: 2 | N3: 96 | O3: +/-0 day | P3: 98 | Q3: 97 | R3: 3 | S3: 6 | T3: 2 | U3: COA,Invoice,Ewaybill,UN Pack Cert (if DG) | V3: 99.7 | W3: 36 | X3: 2 | Y3: 7 | Z3: Ambient | AA3: DG allowed | AB3: 500 KG | AC3: DR200,DR200_UN,IBC1KL | AD3: 2% credit on freight line if OTIF < target (monthly) | AE3: Monthly | AF3: 2026-01-01 | AH3: Active
A4: SLA_STD_DOM_T3 | B4: Domestic Economy T3 (Powders) | C4: DOM | D4: Distributor | E4: ARYLIDE,FLUORO | F4: EXW | G4: 12:00 | H4: Mon-Fri | I4: 2 | J4: 4 | K4: Plant gate | L4: 2 | M4: 5 | N4: 92 | O4: +/-1 day | P4: 96 | Q4: 95 | R4: 7 | S4: 12 | T4: 6 | U4: COA,Invoice | V4: 99 | W4: 72 | X4: 4 | Y4: 15 | Z4: Ambient | AA4: DG by exception | AB4: 1000 KG | AC4: BAG25 only | AD4: No penalties; service credits only for documented failures above 3% of orders | AE4: Semi-Annual | AF4: 2026-01-01 | AH4: Active
A5: SLA_EXPORT_EU_T1 | B5: Export EU T1 (REACH-ready) | C5: EU | D5: Export-Direct,Distributor | E5: ACETYL,DKD,ARYLIDE | F5: FOB/CIF/CIP | G5: 13:00 | H5: Mon-Fri | I5: 3 | J5: 5 | K5: Port (Nhava Sheva/Mundra) | L5: 14 | M5: 21 | N5: 94 | O5: +/-2 days | P5: 97 | Q5: 96 | R5: 10 | S5: 24 | T5: 12 | U5: COA,Invoice,Packing List,SDS,REACH docs,BL | V5: 99.5 | W5: 120 | X5: 5 | Y5: 20 | Z5: Ambient | AA5: DG allowed (IMO) | AB5: 10 MT | AC5: ISO20,Flexitank,DR200_UN | AD5: 1% credit on invoice value if OTIF < target (quarterly) for contract orders | AE5: Quarterly | AF5: 2026-01-01 | AH5: Active
A6: SLA_EXPORT_US_T1_D | B6: Export US T1 (DG capable - Direct) | C6: AMER | D6: Export-Direct | E6: ACETYL,DKD | F6: FOB/CIF | G6: 13:00 | H6: Mon-Fri | I6: 3 | J6: 6 | K6: Port (Nhava Sheva) | L6: 18 | M6: 28 | N6: 93 | O6: +/-3 days | P6: 96 | Q6: 95 | R6: 12 | S6: 24 | T6: 12 | U6: COA,Invoice,Packing List,SDS,TSCA statement,BL | V6: 99.3 | W6: 168 | X6: 5 | Y6: 25 | Z6: Ambient | AA6: DG allowed (IMO) | AB6: 10 MT | AC6: ISO20,DR200_UN | AD6: 2% credit on ocean freight component if OTIF < target (quarterly) | AE6: Quarterly | AF6: 2026-01-01 | AH6: Active
A7: SLA_EXPORT_US_T1_P | B7: Export US T1 (Pharma/High Purity) | C7: AMER | D7: Export-Direct | E7: ACETYL | F7: CIP/DDP (case by case) | G7: 12:00 | H7: Mon-Fri | I7: 2 | J7: 4 | K7: Port + Forwarder handoff | L7: 14 | M7: 24 | N7: 95 | O7: +/-2 days | P7: 98 | Q7: 97 | R7: 8 | S7: 16 | T7: 8 | U7: COA,Invoice,Packing List,SDS,TSCA,Allergen/Pharma statement,BL | V7: 99.7 | W7: 120 | X7: 4 | Y7: 18 | Z7: 46061 | AA7: Non-DG preferred | AB7: 5 MT | AC7: DR200_UN,IBC1KL | AD7: Service credit 1% if documentation accuracy < target; OTIF credits per contract | AE7: Monthly | AF7: 2026-01-01 | AH7: Active
A8: SLA_EXPORT_APAC_T1_D | B8: Export APAC T1 (SEA lanes) | C8: APAC | D8: Export-Direct,Distributor | E8: ACETYL,DKD,FLUORO | F8: FOB/CIF | G8: 14:00 | H8: Mon-Fri | I8: 2 | J8: 5 | K8: Port (Nhava Sheva/Mundra) | L8: 10 | M8: 18 | N8: 94 | O8: +/-2 days | P8: 97 | Q8: 96 | R8: 8 | S8: 18 | T8: 8 | U8: COA,Invoice,Packing List,SDS,BL | V8: 99.2 | W8: 96 | X8: 4 | Y8: 15 | Z8: Ambient | AA8: DG allowed (IMO) | AB8: 5 MT | AC8: ISO20,DR200_UN,IBC1KL | AD8: 0.5% credit if OTIF < target (quarterly) for annual contracts | AE8: Quarterly | AF8: 2026-01-01 | AH8: Active
A9: SLA_EXPORT_APAC_T1_P | B9: Export APAC T1 (Powders) | C9: APAC | D9: Export-Direct,Distributor | E9: ARYLIDE,FLUORO | F9: FOB/CIF | G9: 12:00 | H9: Mon-Fri | I9: 3 | J9: 6 | K9: Port (Nhava Sheva/Mundra) | L9: 12 | M9: 20 | N9: 92 | O9: +/-3 days | P9: 96 | Q9: 95 | R9: 10 | S9: 24 | T9: 12 | U9: COA,Invoice,Packing List,SDS,BL | V9: 99 | W9: 120 | X9: 5 | Y9: 20 | Z9: Ambient | AA9: DG where required | AB9: 3 MT | AC9: BAG25,IBC1KL | AD9: No penalties for port delays; credit applies only for documentation failures | AE9: Semi-Annual | AF9: 2026-01-01 | AH9: Active
A10: SLA_EXPORT_ROW_T2_D | B10: Export ROW T2 (DG/Remote - Direct) | C10: MEA | D10: Export-Direct | E10: ACETYL,DKD,FLUORO | F10: FOB/CFR/CIF | G10: 11:00 | H10: Mon-Fri | I10: 4 | J10: 8 | K10: Port (Nhava Sheva) | L10: 20 | M10: 35 | N10: 90 | O10: +/-4 days | P10: 95 | Q10: 94 | R10: 15 | S10: 30 | T10: 12 | U10: COA,Invoice,Packing List,SDS,BL,Legalization (if required) | V10: 98.8 | W10: 240 | X10: 7 | Y10: 30 | Z10: Ambient | AA10: DG allowed (IMO) | AB10: 10 MT | AC10: ISO20,DR200_UN | AD10: Credits capped at 0.5% of invoice; exclusions for force majeure/port congestion | AE10: Annual | AF10: 2026-01-01 | AH10: Active
A11: SLA_EXPORT_ROW_T2_P | B11: Export ROW T2 (Project/Small lots) | C11: MEA | D11: Distributor | E11: ARYLIDE,FLUORO | F11: EXW/FCA/FOB | G11: 10:00 | H11: Mon-Fri | I11: 5 | J11: 10 | K11: Plant gate / Port | L11: 25 | M11: 45 | N11: 90 | O11: +/-5 days | P11: 95 | Q11: 94 | R11: 20 | S11: 36 | T11: 24 | U11: COA,Invoice,Packing List,SDS | V11: 98.5 | W11: 240 | X11: 8 | Y11: 35 | Z11: Ambient | AA11: DG by exception | AB11: 1000 KG | AC11: BAG25,DR200_UN | AD11: No penalties; review service gaps in QBR and agree corrective actions | AE11: Annual | AF11: 2026-01-01 | AG11: 2026-12-31 | AH11: Planned

Sheet Orders
A1: Order ID (Primary Key) | B1: Order Type | C1: Order Date | D1: Customer ID (FK) | E1: To WH ID | F1: Payment Terms | G1: Order Status
A2: ORD202504-0001 | B2: Transfer Order | C2: 2025-04-01 | E2: TNK_EUR_RTM | F2: Advance | G2: Delivered
A3: ORD202504-0002 | B3: Sales Order | C3: 2025-04-02 | D3: CUS0002 | F3: Net 15 | G3: Delivered
A4: ORD202504-0003 | B4: Sales Order | C4: 2025-04-03 | D4: CUS0003 | F4: Net 30 | G4: Delivered
A5: ORD202504-0004 | B5: Sales Order | C5: 2025-04-04 | D5: CUS0004 | F5: Net 45 | G5: Delivered
A6: ORD202504-0005 | B6: Sales Order | C6: 2025-04-05 | D6: CUS0005 | F6: Advance | G6: Delivered
A7: ORD202504-0006 | B7: Sales Order | C7: 2025-04-06 | D7: CUS0006 | F7: Net 15 | G7: Delivered
A8: ORD202504-0007 | B8: Sales Order | C8: 2025-04-07 | D8: CUS0007 | F8: Net 30 | G8: Delivered
A9: ORD202504-0008 | B9: Transfer Order | C9: 2025-04-08 | E9: WH_IN_SOUTH_HYD | F9: Net 45 | G9: Delivered
A10: ORD202504-0009 | B10: Sales Order | C10: 2025-04-09 | D10: CUS0009 | F10: Advance | G10: Delivered
A11: ORD202504-0010 | B11: Sales Order | C11: 2025-04-10 | D11: CUS0010 | F11: Net 15 | G11: Delivered
A12: ORD202504-0011 | B12: Sales Order | C12: 2025-04-11 | D12: CUS0011 | F12: Net 30 | G12: Delivered
A13: ORD202504-0012 | B13: Sales Order | C13: 2025-04-12 | D13: CUS0012 | F13: Net 45 | G13: Delivered
A14: ORD202504-0013 | B14: Sales Order | C14: 2025-04-13 | D14: CUS0013 | F14: Advance | G14: Delivered
A15: ORD202504-0014 | B15: Sales Order | C15: 2025-04-14 | D15: CUS0014 | F15: Net 15 | G15: Delivered
A16: ORD202504-0015 | B16: Transfer Order | C16: 2025-04-15 | E16: TNK_EUR_RTM | F16: Net 30 | G16: Delivered
A17: ORD202504-0016 | B17: Sales Order | C17: 2025-04-16 | D17: CUS0016 | F17: Net 45 | G17: Delivered
A18: ORD202504-0017 | B18: Sales Order | C18: 2025-04-17 | D18: CUS0017 | F18: Advance | G18: Delivered
A19: ORD202504-0018 | B19: Sales Order | C19: 2025-04-18 | D19: CUS0018 | F19: Net 15 | G19: Delivered
A20: ORD202504-0019 | B20: Sales Order | C20: 2025-04-19 | D20: CUS0019 | F20: Net 30 | G20: Delivered
A21: ORD202504-0020 | B21: Sales Order | C21: 2025-04-20 | D21: CUS0020 | F21: Net 45 | G21: Delivered
A22: ORD202504-0021 | B22: Sales Order | C22: 2025-04-21 | D22: CUS0021 | F22: Advance | G22: Delivered
A23: ORD202504-0022 | B23: Transfer Order | C23: 2025-04-22 | E23: WH_IN_SOUTH_HYD | F23: Net 15 | G23: Delivered
A24: ORD202504-0023 | B24: Sales Order | C24: 2025-04-23 | D24: CUS0023 | F24: Net 30 | G24: Delivered
A25: ORD202504-0024 | B25: Sales Order | C25: 2025-04-24 | D25: CUS0024 | F25: Net 45 | G25: Delivered
A26: ORD202504-0025 | B26: Sales Order | C26: 2025-04-25 | D26: CUS0025 | F26: Advance | G26: Delivered
A27: ORD202504-0026 | B27: Sales Order | C27: 2025-04-26 | D27: CUS0026 | F27: Net 15 | G27: Delivered
A28: ORD202504-0027 | B28: Sales Order | C28: 2025-04-27 | D28: CUS0027 | F28: Net 30 | G28: Delivered
A29: ORD202504-0028 | B29: Sales Order | C29: 2025-04-28 | D29: CUS0028 | F29: Net 45 | G29: Delivered
A30: ORD202504-0029 | B30: Transfer Order | C30: 2025-04-29 | E30: TNK_EUR_RTM | F30: Advance | G30: Delivered
A31: ORD202504-0030 | B31: Sales Order | C31: 2025-04-30 | D31: CUS0030 | F31: Net 15 | G31: Delivered
A32: ORD202504-0031 | B32: Sales Order | C32: 2025-04-01 | D32: CUS0031 | F32: Net 30 | G32: Delivered
A33: ORD202504-0032 | B33: Sales Order | C33: 2025-04-02 | D33: CUS0032 | F33: Net 45 | G33: Delivered
A34: ORD202504-0033 | B34: Sales Order | C34: 2025-04-03 | D34: CUS0033 | F34: Advance | G34: Delivered
A35: ORD202504-0034 | B35: Sales Order | C35: 2025-04-04 | D35: CUS0034 | F35: Net 15 | G35: Delivered
A36: ORD202504-0035 | B36: Sales Order | C36: 2025-04-05 | D36: CUS0035 | F36: Net 30 | G36: Delivered
A37: ORD202504-0036 | B37: Transfer Order | C37: 2025-04-06 | E37: WH_IN_SOUTH_HYD | F37: Net 45 | G37: Delivered
A38: ORD202504-0037 | B38: Sales Order | C38: 2025-04-07 | D38: CUS0037 | F38: Advance | G38: Delivered
A39: ORD202504-0038 | B39: Sales Order | C39: 2025-04-08 | D39: CUS0038 | F39: Net 15 | G39: Delivered
A40: ORD202504-0039 | B40: Sales Order | C40: 2025-04-09 | D40: CUS0039 | F40: Net 30 | G40: Delivered
...

Sheet Order_Line Items
A1: Order Line Item (Primary Key) | B1: Order_id (FK) | C1: SLA Profile ID (FK) | D1: Delivery_by_date | E1: Requirement Status | F1: Fulfilled by WH ID (WH ID FK) | G1: SKU ID (FK) | H1: Quantity | I1: Unit Price (USD) | J1: Value (USD) | K1: Forecast ID (FK)
A2: OLI202504-0001 | B2: ORD202504-0001 | C2: SLA_STD_DOM_T1 | D2: 2025-04-08 | E2: Fulfilled | F2: TNK_EUR_RTM | G2: ESS-ACETYL-ETHACE-LM-98.5-NEAT-BULK-DST | H2: 21 | I2: 1000 | J2: 21000 | K2: FC202504-DOM-ACETYL
A3: OLI202504-0002 | B3: ORD202504-0002 | C3: SLA_STD_DOM_T2 | D3: 2025-04-10 | E3: Fulfilled | F3: TNK_EUR_ANT | G3: ESS-ACETYL-ETHACE-LM-98.5-NEAT-BULK-DST | H3: 22 | I3: 1001 | J3: 22022 | K3: FC202504-EU-DKD
A4: OLI202504-0003 | B4: ORD202504-0003 | C4: SLA_STD_DOM_T3 | D4: 2025-04-12 | E4: Fulfilled | F4: TNK_EUR_GEN | G4: ESS-ACETYL-ETHACE-LM-98.5-NEAT-BULK-DST | H4: 23 | I4: 1002 | J4: 23046 | K4: FC202504-AMER-ARYLIDE
A5: OLI202504-0004 | B5: ORD202504-0004 | C5: SLA_EXPORT_EU_T1 | D5: 2025-04-14 | E5: Fulfilled | F5: WH_EU_DEU_HAM | G5: SPI-ACETYL-ACEANH-PH-98.6-NEAT-DR200_UN-MHD | H5: 24 | I5: 1003 | J5: 24072 | K5: FC202504-APAC-FLUORO
A6: OLI202504-0005 | B6: ORD202504-0005 | C6: SLA_EXPORT_US_T1_D | D6: 2025-04-16 | E6: Fulfilled | F6: CFS_IN_NHAV | G6: SPI-ACETYL-ACEANH-PH-98.6-NEAT-DR200_UN-MHD | H6: 25 | I6: 1004 | J6: 25100 | K6: FC202504-MEA-ACETYL
A7: OLI202504-0006 | B7: ORD202504-0006 | C7: SLA_EXPORT_US_T1_P | D7: 2025-04-18 | E7: Fulfilled | F7: WH_IN_WEST_BHI | G7: SPI-ACETYL-ACEANH-PH-98.6-NEAT-DR200_UN-MHD | H7: 26 | I7: 1005 | J7: 26130 | K7: FC202504-ROW-DKD
A8: OLI202504-0007 | B8: ORD202504-0007 | C8: SLA_EXPORT_APAC_T1_D | D8: 2025-04-20 | E8: Fulfilled | F8: WH_IN_GUJ_AHD | G8: SPI-ACETYL-ACE-IND-98.4-NEAT-ISO20-LTE | H8: 27 | I8: 1006 | J8: 27162 | K8: FC202504-DOM-ARYLIDE
A9: OLI202504-0008 | B9: ORD202504-0008 | C9: SLA_EXPORT_APAC_T1_P | D9: 2025-04-22 | E9: Fulfilled | F9: WH_IN_SOUTH_HYD | G9: SPI-ACETYL-ACE-IND-98.4-NEAT-ISO20-LTE | H9: 28 | I9: 1007 | J9: 28196 | K9: FC202504-EU-FLUORO
A10: OLI202504-0009 | B10: ORD202504-0009 | C10: SLA_EXPORT_ROW_T2_D | D10: 2025-04-24 | E10: Fulfilled | F10: WH_IN_NORTH_BAW | G10: SPI-ACETYL-ACE-IND-98.4-NEAT-ISO20-LTE | H10: 29 | I10: 1008 | J10: 29232 | K10: FC202504-AMER-ACETYL
A11: OLI202504-0010 | B11: ORD202504-0010 | C11: SLA_EXPORT_ROW_T2_P | D11: 2025-04-26 | E11: Fulfilled | F11: WH_IN_EAST_KOL | G11: ESS-ACETYL-BUTACE-TECH-98.3-NEAT-DR200-DHJ | H11: 30 | I11: 1009 | J11: 30270 | K11: FC202504-APAC-DKD
A12: OLI202504-0011 | B12: ORD202504-0011 | C12: SLA_STD_DOM_T1 | D12: 2025-04-28 | E12: Fulfilled | F12: WH_US_EAST_NJ | G12: ESS-ACETYL-BUTACE-TECH-98.3-NEAT-DR200-DHJ | H12: 31 | I12: 1010 | J12: 31310 | K12: FC202504-MEA-ARYLIDE
A13: OLI202504-0012 | B13: ORD202504-0012 | C13: SLA_STD_DOM_T2 | D13: 2025-04-28 | E13: Fulfilled | F13: WH_US_MID_CHI | G13: ESS-ACETYL-BUTACE-TECH-98.3-NEAT-DR200-DHJ | H13: 32 | I13: 1011 | J13: 32352 | K13: FC202504-ROW-FLUORO
... A217: OLI202504-0216 | B217: ORD202504-0036 | C217: SLA_EXPORT_US_T1_P | D217: 2025-04-18 | E217: Fulfilled | F217: WH_IN_WEST_BHI | G217: ESS-ACETYL-ACEANH-PH-99.7-NEAT-ISO20-DHJ | H217: 55 | I217: 1215 | J217: 66825 | K217: FC202504-ROW-FLUORO
A218: OLI202505-0217 | B218: ORD202505-0001 | C218: SLA_STD_DOM_T1 | D218: 45785 | E218: Fulfilled | F218: TNK_EUR_RTM | G218: ESS-ACETYL-ETHACE-LM-98.5-NEAT-BULK-DST | H218: 56 | I218: 1000 | J218: 56000 | K218: FC202505-DOM-ACETYL
A219: OLI202505-0218 | B219: ORD202505-0002 | C219: SLA_STD_DOM_T2 | D219: 45787 | E219: Fulfilled | F219: TNK_EUR_ANT | G219: ESS-ACETYL-ETHACE-LM-98.5-NEAT-BULK-DST | H219: 57 | I219: 1001 | J219: 57057 | K219: FC202505-EU-DKD
A220: OLI202505-0219 | B220: ORD202505-0003 | C220: SLA_STD_DOM_T3 | D220: 45789 | E220: Fulfilled | F220: TNK_EUR_GEN | G220: ESS-ACETYL-ETHACE-LM-98.5-NEAT-BULK-DST | H220: 58 | I220: 1002 | J220: 58116 | K220: FC202505-AMER-ARYLIDE
A221: OLI202505-0220 | B221: ORD202505-0004 | C221: SLA_EXPORT_EU_T1 | D221: 45791 | E221: Fulfilled | F221: WH_EU_DEU_HAM | G221: SPI-ACETYL-ACEANH-PH-98.6-NEAT-DR200_UN-MHD | H221: 59 | I221: 1003 | J221: 59177 | K221: FC202505-APAC-FLUORO
A222: OLI202505-0221 | B222: ORD202505-0005 | C222: SLA_EXPORT_US_T1_D | D222: 45793 | E222: Fulfilled | F222: CFS_IN_NHAV | G222: SPI-ACETYL-ACEANH-PH-98.6-NEAT-DR200_UN-MHD | H222: 60 | I222: 1004 | J222: 60240 | K222: FC202505-MEA-ACETYL
A223: OLI202505-0222 | B223: ORD202505-0006 | C223: SLA_EXPORT_US_T1_P | D223: 45795 | E223: Fulfilled | F223: WH_IN_WEST_BHI | G223: SPI-ACETYL-ACEANH-PH-98.6-NEAT-DR200_UN-MHD | H223: 61 | I223: 1005 | J223: 61305 | K223: FC202505-ROW-DKD
A224: OLI202505-0223 | B224: ORD202505-0007 | C224: SLA_EXPORT_APAC_T1_D | D224: 45797 | E224: Fulfilled | F224: WH_IN_GUJ_AHD | G224: SPI-ACETYL-ACE-IND-98.4-NEAT-ISO20-LTE | H224: 62 | I224: 1006 | J224: 62372 | K224: FC202505-DOM-ARYLIDE
A225: OLI202505-0224 | B225: ORD202505-0008 | C225: SLA_EXPORT_APAC_T1_P | D225: 45799 | E225: Fulfilled | F225: WH_IN_SOUTH_HYD | G225: SPI-ACETYL-ACE-IND-98.4-NEAT-ISO20-LTE | H225: 63 | I225: 1007 | J225: 63441 | K225: FC202505-EU-FLUORO
A226: OLI202505-0225 | B226: ORD202505-0009 | C226: SLA_EXPORT_ROW_T2_D | D226: 45801 | E226: Fulfilled | F226: WH_IN_NORTH_BAW | G226: SPI-ACETYL-ACE-IND-98.4-NEAT-ISO20-LTE | H226: 64 | I226: 1008 | J226: 64512 | K226: FC202505-AMER-ACETYL
A227: OLI202505-0226 | B227: ORD202505-0010 | C227: SLA_EXPORT_ROW_T2_P | D227: 45803 | E227: Fulfilled | F227: WH_IN_EAST_KOL | G227: ESS-ACETYL-BUTACE-TECH-98.3-NEAT-DR200-DHJ | H227: 65 | I227: 1009 | J227: 65585 | K227: FC202505-APAC-DKD
A228: OLI202505-0227 | B228: ORD202505-0011 | C228: SLA_STD_DOM_T1 | D228: 45805 | E228: Fulfilled | F228: WH_US_EAST_NJ | G228: ESS-ACETYL-BUTACE-TECH-98.3-NEAT-DR200-DHJ | H228: 66 | I228: 1010 | J228: 66660 | K228: FC202505-MEA-ARYLIDE
A229: OLI202505-0228 | B229: ORD202505-0012 | C229: SLA_STD_DOM_T2 | D229: 45805 | E229: Fulfilled | F229: WH_US_MID_CHI | G229: ESS-ACETYL-BUTACE-TECH-98.3-NEAT-DR200-DHJ | H229: 67 | I229: 1011 | J229: 67737 | K229: FC202505-ROW-FLUORO
... A2593: OLI202603-2592 | B2593: ORD202603-0036 | C2593: SLA_EXPORT_US_T1_P | D2593: 46123 | E2593: Pending | F2593: WH_IN_WEST_BHI | G2593: ESS-ACETYL-ACEANH-PH-99.7-NEAT-ISO20-DHJ | H2593: 78 | I2593: 1215 | J2593: 94770 | K2593: FC202603-ROW-FLUORO

Sheet Signals
A1: Signal ID (Primary Key) | B1: Source | C1: Topic headline | D1: Description | E1: Sentiment Score | F1: Confidence | G1: Detected On_Date | H1: Signal Type | I1: Forecast ID (FK) | J1: Exception ID (FK)
A2: SIG202504-0001 | B2: News (ICIS) | C2: European ethanol tightness lifts solvent feedstock costs | D2: European ethanol tightness lifts solvent feedstock costs. Monitor and adjust ACETYL planning accordingly. | E2: -0.30 | F2: 0.65 | G2: 45748 | H2: forecast input | I2: FC202504-DOM-ACETYL
A3: SIG202504-0002 | B3: Finance note (FX/credit) | C3: INR volatility may impact import cost for methacrylic acid | D3: INR volatility may impact import cost for methacrylic acid. Monitor and adjust DKD planning accordingly. | E3: -0.15 | F3: 0.73 | G3: 45755 | H3: forecast input | I3: FC202504-EU-DKD
A4: SIG202504-0003 | B4: Internal memo (Plant Ops) | C4: Plant running stable at higher throughputs | D4: Plant running stable at higher throughputs. Monitor and adjust ARYLIDE planning accordingly. | E4: 0.00 | F4: 0.81 | G4: 45762 | H4: forecast input | I4: FC202504-AMER-ARYLIDE
A5: SIG202504-0004 | B5: LSP bulletin | C5: Port congestion warning for DG containers | D5: Port congestion warning for DG containers. Monitor and adjust FLUORO planning accordingly. | E5: 0.15 | F5: 0.89 | G5: 45769 | H5: exception | J5: EXC202504-0001
A6: SIG202505-0005 | B6: News (ICIS) | C6: Customer requests additional packaging availability | D6: Customer requests additional packaging availability. Monitor and adjust ACETYL planning accordingly. | E6: -0.30 | F6: 0.65 | G6: 45778 | H6: forecast input | I6: FC202505-DOM-ACETYL
A7: SIG202505-0006 | B7: Finance note (FX/credit) | C7: Freight rates soften on Asia-Europe lane | D7: Freight rates soften on Asia-Europe lane. Monitor and adjust DKD planning accordingly. | E7: -0.15 | F7: 0.73 | G7: 45785 | H7: forecast input | I7: FC202505-EU-DKD
A8: SIG202505-0007 | B8: Internal memo (Plant Ops) | C8: Distributor asking for extended credit | D8: Distributor asking for extended credit. Monitor and adjust ARYLIDE planning accordingly. | E8: 0.00 | F8: 0.81 | G8: 45792 | H8: forecast input | I8: FC202505-AMER-ARYLIDE
A9: SIG202505-0008 | B9: LSP bulletin | C9: Acetic acid spot prices firm on maintenance | D9: Acetic acid spot prices firm on maintenance. Monitor and adjust FLUORO planning accordingly. | E9: 0.15 | F9: 0.89 | G9: 45799 | H9: exception | J9: EXC202505-0005
A10: SIG202506-0009 | B10: News (ICIS) | C10: Scheduling constraint for DG packaging | D10: Scheduling constraint for DG packaging. Monitor and adjust ACETYL planning accordingly. | E10: -0.30 | F10: 0.65 | G10: 45809 | H10: forecast input | I10: FC202506-DOM-ACETYL
A11: SIG202506-0010 | B11: Finance note (FX/credit) | C11: Supply chain disruption alert | D11: Supply chain disruption alert. Monitor and adjust DKD planning accordingly. | E11: -0.15 | F11: 0.73 | G11: 45816 | H11: forecast input | I11: FC202506-EU-DKD
A12: SIG202506-0011 | B12: Internal memo (Plant Ops) | C12: European ethanol tightness lifts solvent feedstock costs | D12: European ethanol tightness lifts solvent feedstock costs. Monitor and adjust ARYLIDE planning accordingly. | E12: 0.00 | F12: 0.81 | G12: 45823 | H12: forecast input | I12: FC202506-AMER-ARYLIDE
A13: SIG202506-0012 | B13: LSP bulletin | C13: INR volatility may impact import cost for methacrylic acid | D13: INR volatility may impact import cost for methacrylic acid. Monitor and adjust FLUORO planning accordingly. | E13: 0.15 | F13: 0.89 | G13: 45830 | H13: exception | J13: EXC202506-0008
A14: SIG202507-0013 | B14: News (ICIS) | C14: Plant running stable at higher throughputs | D14: Plant running stable at higher throughputs. Monitor and adjust ACETYL planning accordingly. | E14: -0.30 | F14: 0.65 | G14: 45839 | H14: forecast input | I14: FC202507-DOM-ACETYL
A15: SIG202507-0014 | B15: Finance note (FX/credit) | C15: Port congestion warning for DG containers | D15: Port congestion warning for DG containers. Monitor and adjust DKD planning accordingly. | E15: -0.15 | F15: 0.73 | G15: 45846 | H15: forecast input | I15: FC202507-EU-DKD
